<?xml version="1.0" encoding="utf-8"?>
<robot name="s2a_body">

  <link name="base_footprint">
  </link>
  <joint name="base_footprint_joint" type="fixed">
    <parent link="base_footprint" />
    <child link="base_link" />
  </joint>

  <link name="base_link">
    <inertial>
      <origin xyz="-0.00183994912012901 0.000718384784481402 0.040896257051146" rpy="0 0 0" />
      <mass value="2.11446326748896" />
      <inertia ixx="0.0172522550977486" ixy="0.000112962512291742" ixz="0.00215471233797688"
        iyy="0.0214703513066925" iyz="-3.60344762320202E-05" izz="0.0232865128652866" />
    </inertial>
    <visual>
      <origin xyz="0 0 0" rpy="0 0 0" />
      <geometry>
        <mesh filename="package://zx_description/meshes/W2A/base_link.STL" />
      </geometry>
      <material name="">
        <color rgba="0.898039215686275 0.917647058823529 0.929411764705882 1" />
      </material>
    </visual>
    <collision>
      <origin xyz="0 0 0" rpy="0 0 0" />
      <geometry>
        <mesh filename="package://zx_description/meshes/W2A/base_link.STL" />
      </geometry>
    </collision>
  </link>
  <gazebo reference="base_link">
    <material>Gazebo/Gray</material>
  </gazebo>

  <link name="laser_link">
    <inertial>
      <origin xyz="0.000353208493461253 1.96691527473355E-07 -0.0201221997898385" rpy="0 0 0" />
      <mass value="0.0286837286205052" />
      <inertia ixx="1.36744565408129E-05" ixy="2.21134123619835E-07" ixz="4.73474118879471E-10"
        iyy="9.81480326700524E-06" iyz="7.43216749293828E-12" izz="1.6701788304723E-05" />
    </inertial>
    <visual>
      <origin xyz="0 0 0" rpy="0 0 0" />
      <geometry>
        <mesh filename="package://zx_description/meshes/W2A/laser_Link.STL" />
      </geometry>
      <material name="">
        <color rgba="0.752941176470588 1 1 1" />
      </material>
    </visual>
    <collision>
      <origin xyz="0 0 0" rpy="0 0 0" />
      <geometry>
        <mesh filename="package://zx_description/meshes/W2A/laser_Link.STL" />
      </geometry>
    </collision>
  </link>
  <joint name="laser_joint" type="fixed">
    <origin xyz="0.00103030119583913 0.00720522416129914 0.1163755467821167" rpy="0 0 0" />
    <parent link="base_link" />
    <child link="laser_link" />
    <axis xyz="0 0 0" />
  </joint>
  <gazebo reference="laser_link">
    <material>Gazebo/Gray</material>
  </gazebo>

  <link name="wheel_L_Link">
    <inertial>
      <origin xyz="-3.78770996317668E-07 -0.0144142505941949 4.81266645285805E-07" rpy="0 0 0" />
      <mass value="0.337836569375269" />
      <inertia
        ixx="0.000278270805900081"
        ixy="1.29138084143892E-09"
        ixz="1.09699819030856E-09"
        iyy="0.000496405737651082"
        iyz="-1.64156177606666E-09"
        izz="0.000278271727426874" />
    </inertial>
    <visual>
      <origin xyz="0 0 0" rpy="0 0 0" />
      <geometry>
        <mesh filename="package://zx_description/meshes/W2A/wheel_L_Link.STL" />
      </geometry>
      <material name="">
        <color rgba="0.752941176470588 0.752941176470588 0.752941176470588 1" />
      </material>
    </visual>
    <collision>
      <origin xyz="0 0 0" rpy="0 0 0" />
      <geometry>
        <mesh filename="package://zx_description/meshes/W2A/wheel_L_Link.STL" />
      </geometry>
    </collision>
  </link>
  <joint name="wheel_L_joint" type="continuous">
    <origin xyz="0 0.1225 -0.021" rpy="0 0 0" />
    <parent link="base_link" />
    <child link="wheel_L_Link" />
    <axis xyz="0 1 0" />
  </joint>
  <gazebo reference="wheel_L_Link">
    <material>Gazebo/Gray</material>
  </gazebo>

  <link name="wheel_R_Link">
    <inertial>
      <origin xyz="-5.54575135314206E-07 0.014414250594195 2.59868179627865E-07" rpy="0 0 0" />
      <mass value="0.337836569375269" />
      <inertia
        ixx="0.000278271195902001"
        ixy="-1.89148049640787E-09"
        ixz="1.18772924120536E-09"
        iyy="0.000496405737651081"
        iyz="8.85827903431854E-10"
        izz="0.000278271337424953" />
    </inertial>
    <visual>
      <origin xyz="0 0 0" rpy="0 0 0" />
      <geometry>
        <mesh filename="package://zx_description/meshes/W2A/wheel_R_Link.STL" />
      </geometry>
      <material name="">
        <color rgba="0.752941176470588 0.752941176470588 0.752941176470588 1" />
      </material>
    </visual>
    <collision>
      <origin xyz="0 0 0" rpy="0 0 0" />
      <geometry>
        <mesh filename="package://zx_description/meshes/W2A/wheel_R_Link.STL" />
      </geometry>
    </collision>
  </link>
  <joint name="wheel_R_joint" type="continuous">
    <origin xyz="0 -0.1225 -0.021" rpy="0 0 0" />
    <parent link="base_link" />
    <child link="wheel_R_Link" />
    <axis xyz="0 1 0" />
  </joint>
  <gazebo reference="wheel_R_Link">
    <material>Gazebo/Gray</material>
  </gazebo>

  <!-- <link name="front_Link">
    <inertial>
      <origin xyz="0 0 0" rpy="0 0 0" />
      <mass value="0.0063074121665526" />
      <inertia ixx="3.34755925557046E-07" ixy="-1.45392467961487E-22" ixz="2.42001994301979E-24"
        iyy="4.93530086138426E-07" iyz="6.44209161389679E-25" izz="3.34755925557046E-07" />
    </inertial>
    <visual>
      <origin xyz="0 0 0" rpy="0 0 0" />
      <geometry>
        <mesh filename="package://zx_description/meshes/W2A/wheel_B_Link.STL" />
      </geometry>
      <material name="">
        <color rgba="0.752941176470588 1 1 1" />
      </material>
    </visual>
    <collision>
      <origin xyz="0 0 0" rpy="0 0 0" />
      <geometry>
        <mesh filename="package://zx_description/meshes/W2A/wheel_B_Link.STL" />
      </geometry>
    </collision>
  </link>
  <joint name="front_joint" type="continuous">
    <origin xyz="0.0859999999999999 0 -0.0575" rpy="0 0 0" />
    <parent link="base_link" />
    <child link="front_Link" />
    <axis xyz="0 -1 0" />
  </joint>

  <link name="back_Link">
    <inertial>
      <origin xyz="0 0 0" rpy="0 0 0" />
      <mass value="0.0063074121665526" />
      <inertia ixx="3.34755925557046E-07" ixy="-1.45392467961487E-22" ixz="2.42001994301979E-24"
        iyy="4.93530086138426E-07" iyz="6.4420916138968E-25" izz="3.34755925557046E-07" />
    </inertial>
    <visual>
      <origin xyz="0 0 0" rpy="0 0 0" />
      <geometry>
        <mesh filename="package://zx_description/meshes/W2A/wheel_A_Link.STL" />
      </geometry>
      <material name="">
        <color rgba="0.752941176470588 1 1 1" />
      </material>
    </visual>
    <collision>
      <origin xyz="0 0 0" rpy="0 0 0" />
      <geometry>
        <mesh filename="package://zx_description/meshes/W2A/wheel_A_Link.STL" />
      </geometry>
    </collision>
  </link>
  <joint name="back_joint" type="continuous">
    <origin xyz="-0.0859999999999998 0 -0.0575" rpy="0 0 0" />
    <parent link="base_link" />
    <child link="back_Link" />
    <axis xyz="0 -1 0" />
  </joint> -->

  <link name="arm_base_link">
    <inertial>
      <origin xyz="-1.7947E-07 -0.0018392 0.042093" rpy="0 0 0" />
      <mass value="0.14029" />
      <inertia ixx="0.00016721" ixy="-1.4903E-10" ixz="-3.0653E-10" iyy="0.00016551"
        iyz="-2.4534E-06" izz="0.0001699" />
    </inertial>
    <visual>
      <origin xyz="0 0 0" rpy="0 0 0" />
      <geometry>
        <mesh filename="package://zx_description/meshes/W2A/arm/arm_base_link.STL" />
      </geometry>
      <material name="">
        <color rgba="0.2 0.2 0.2 1" />
      </material>
    </visual>
    <collision>
      <origin xyz="0 0 0" rpy="0 0 0" />
      <geometry>
        <mesh filename="package://zx_description/meshes/W2A/arm/arm_base_link.STL" />
      </geometry>
    </collision>
  </link>
  <joint name="arm_joint" type="fixed">
    <origin xyz="-0.0003030119583913 0.00020522416129914 0.1363755467821167" rpy="0 0 -1.5707" />
    <parent link="base_link" />
    <child link="arm_base_link" />
    <axis xyz="0 0 0" />
  </joint>
  <gazebo reference="arm_base_link">
    <material>Gazebo/Gray</material>
  </gazebo>

  <link name="link_1">
    <inertial>
      <origin xyz="0.00015999 -3.7029E-07 0.0067201" rpy="0 0 0" />
      <mass value="0.068148" />
      <inertia ixx="3.0609E-05" ixy="-5.9099E-11" ixz="-1.3841E-07" iyy="3.6584E-05"
        iyz="4.9301E-10" izz="2.3547E-05" />
    </inertial>
    <visual>
      <origin xyz="0 0 0" rpy="0 0 0" />
      <geometry>
        <mesh filename="package://zx_description/meshes/W2A/arm/link_1.STL" />
      </geometry>
      <material name="">
        <color rgba="0.2 0.2 0.2 1" />
      </material>
    </visual>
    <collision>
      <origin xyz="0 0 0" rpy="0 0 0" />
      <geometry>
        <mesh filename="package://zx_description/meshes/W2A/arm/link_1.STL" />
      </geometry>
    </collision>
  </link>
  <joint name="joint_1" type="revolute">
    <origin xyz="0 0 0.072247" rpy="0 0 0" />
    <parent link="arm_base_link" />
    <child link="link_1" />
    <axis xyz="0 0 1" />
    <limit lower="-1.8" upper="1.8" effort="50" velocity="2" />
  </joint>
  <gazebo reference="link_1">
    <material>Gazebo/Gray</material>
  </gazebo>

  <link name="link_2">
    <inertial>
      <origin xyz="0.028477 -5.0821E-07 0.038913" rpy="0 0 0" />
      <mass value="0.049654" />
      <inertia ixx="1.8351E-05" ixy="-6.0792E-11" ixz="-6.4071E-08" iyy="3.1671E-05"
        iyz="3.6197E-10" izz="1.6517E-05" />
    </inertial>
    <visual>
      <origin xyz="0 0 0" rpy="0 0 0" />
      <geometry>
        <mesh filename="package://zx_description/meshes/W2A/arm/link_2.STL" />
      </geometry>
      <material name="">
        <color rgba="0.2 0.2 0.2 1" />
      </material>
    </visual>
    <collision>
      <origin xyz="0 0 0" rpy="0 0 0" />
      <geometry>
        <mesh filename="package://zx_description/meshes/W2A/arm/link_2.STL" />
      </geometry>
    </collision>
  </link>
  <joint name="joint_2" type="revolute">
    <origin xyz="-0.028151 0 0.034" rpy="0 0 0" />
    <parent link="link_1" />
    <child link="link_2" />
    <axis xyz="1 0 0" />
    <limit lower="-1.8" upper="1.8" effort="50" velocity="3" />
  </joint>
  <gazebo reference="link_2">
    <material>Gazebo/Gray</material>
  </gazebo>

  <link name="link_3">
    <inertial>
      <origin xyz="0.028363 -4.679E-07 0.054247" rpy="0 0 0" />
      <mass value="0.053931" />
      <inertia ixx="3.1912E-05" ixy="-6.0429E-11" ixz="-9.8626E-08" iyy="4.873E-05" iyz="4.797E-10"
        izz="2.0341E-05" />
    </inertial>
    <visual>
      <origin xyz="0 0 0" rpy="0 0 0" />
      <geometry>
        <mesh filename="package://zx_description/meshes/W2A/arm/link_3.STL" />
      </geometry>
      <material name="">
        <color rgba="0.2 0.2 0.2 1" />
      </material>
    </visual>
    <collision>
      <origin xyz="0 0 0" rpy="0 0 0" />
      <geometry>
        <mesh filename="package://zx_description/meshes/W2A/arm/link_3.STL" />
      </geometry>
    </collision>
  </link>
  <joint name="joint_3" type="revolute">
    <origin xyz="9.8516E-05 0 0.061" rpy="0 0 0" />
    <parent link="link_2" />
    <child link="link_3" />
    <axis xyz="1 0 0" />
    <limit lower="-1.8" upper="1.8" effort="50" velocity="3" />
  </joint>
  <gazebo reference="link_3">
    <material>Gazebo/Gray</material>
  </gazebo>

  <link name="link_4">
    <inertial>
      <origin xyz="0.028255 -0.0047504 0.06611" rpy="0 0 0" />
      <mass value="0.10537" />
      <inertia ixx="9.6221E-05" ixy="-3.6252E-10" ixz="2.7529E-08" iyy="7.3811E-05" iyz="7.9136E-06"
        izz="6.9537E-05" />
    </inertial>
    <visual>
      <origin xyz="0 0 0" rpy="0 0 0" />
      <geometry>
        <mesh filename="package://zx_description/meshes/W2A/arm/link_4.STL" />
      </geometry>
      <material name="">
        <color rgba="0.2 0.2 0.2 1" />
      </material>
    </visual>
    <collision>
      <origin xyz="0 0 0" rpy="0 0 0" />
      <geometry>
        <mesh filename="package://zx_description/meshes/W2A/arm/link_4.STL" />
      </geometry>
    </collision>
  </link>
  <joint name="joint_4" type="revolute">
    <origin xyz="0 0 0.081" rpy="0 0 0" />
    <parent link="link_3" />
    <child link="link_4" />
    <axis xyz="1 0 0" />
    <limit lower="-1.8" upper="1.8" effort="50" velocity="3" />
  </joint>
  <gazebo reference="link_4">
    <material>Gazebo/Gray</material>
  </gazebo>

  <link name="link_5">
    <inertial>
      <origin xyz="4.4212E-05 0.0041269 0.025698" rpy="0 0 0" />
      <mass value="0.098063" />
      <inertia ixx="3.7917E-05" ixy="1.4713E-07" ixz="-1.1994E-07" iyy="5.5952E-05" iyz="2.3438E-06"
        izz="5.2518E-05" />
    </inertial>
    <visual>
      <origin xyz="0 0 0" rpy="0 0 0" />
      <geometry>
        <mesh filename="package://zx_description/meshes/W2A/arm/link_5.STL" />
      </geometry>
      <material name="">
        <color rgba="0.2 0.2 0.2 1" />
      </material>
    </visual>
    <collision>
      <origin xyz="0 0 0" rpy="0 0 0" />
      <geometry>
        <mesh filename="package://zx_description/meshes/W2A/arm/link_5.STL" />
      </geometry>
    </collision>
  </link>
  <joint name="joint_5" type="revolute">
    <origin xyz="0.02825 0 0.0975" rpy="0 0 0" />
    <parent link="link_4" />
    <child link="link_5" />
    <axis xyz="0 0 -1" />
    <limit lower="-1.8" upper="1.8" effort="50" velocity="3" />
  </joint>
  <gazebo reference="link_5">
    <material>Gazebo/Gray</material>
  </gazebo>

  <link name="claw_link_1">
    <inertial>
      <origin xyz="0.0054256 -0.015308 0.019147" rpy="0 0 0" />
      <mass value="0.018231" />
      <inertia ixx="6.9914E-06" ixy="-3.7017E-08" ixz="1.3043E-06" iyy="6.7797E-06" iyz="4.9174E-08"
        izz="2.5386E-06" />
    </inertial>
    <visual>
      <origin xyz="0 0 0" rpy="0 0 0" />
      <geometry>
        <mesh filename="package://zx_description/meshes/W2A/arm/claw_link_1.STL" />
      </geometry>
      <material name="">
        <color rgba="0.2 0.2 0.2 1" />
      </material>
    </visual>
    <collision>
      <origin xyz="0 0 0" rpy="0 0 0" />
      <geometry>
        <mesh filename="package://zx_description/meshes/W2A/arm/claw_link_1.STL" />
      </geometry>
    </collision>
  </link>
  <joint name="claw_joint_1" type="revolute">
    <origin xyz="-0.028 0.015 0.0462" rpy="0 0 0" />
    <parent link="link_5" />
    <child link="claw_link_1" />
    <axis xyz="0 -1 0" />
    <limit lower="-1.5" upper="1.5" effort="10" velocity="3" />
  </joint>
  <gazebo reference="claw_link_1">
    <material>Gazebo/Gray</material>
  </gazebo>

  <link name="claw_link_2">
    <inertial>
      <origin xyz="-0.0054256 -0.015308 0.019147" rpy="0 0 0" />
      <mass value="0.018231" />
      <inertia ixx="6.9914E-06" ixy="3.7016E-08" ixz="-1.3043E-06" iyy="6.7797E-06" iyz="4.9173E-08"
        izz="2.5386E-06" />
    </inertial>
    <visual>
      <origin xyz="0 0 0" rpy="0 0 0" />
      <geometry>
        <mesh filename="package://zx_description/meshes/W2A/arm/claw_link_2.STL" />
      </geometry>
      <material name="">
        <color rgba="0.2 0.2 0.2 1" />
      </material>
    </visual>
    <collision>
      <origin xyz="0 0 0" rpy="0 0 0" />
      <geometry>
        <mesh filename="package://zx_description/meshes/W2A/arm/claw_link_2.STL" />
      </geometry>
    </collision>
  </link>
  <joint name="claw_joint_2" type="revolute">
    <origin xyz="0.027609 0.015 0.0462" rpy="0 0 0" />
    <parent link="link_5" />
    <child link="claw_link_2" />
    <axis xyz="0 -1 0" />
    <limit lower="-1.5" upper="1.5" effort="10" velocity="3" />
  </joint>
  <gazebo reference="claw_link_2">
    <material>Gazebo/Gray</material>
  </gazebo>

</robot>